<?xml version="1.0" ?>
<!-- =================================================================================== -->
<!-- |    This document was autogenerated by xacro from crb15000_5_95.xacro          | -->
<!-- |    EDITING THIS FILE BY HAND IS NOT RECOMMENDED                                 | -->
<!-- =================================================================================== -->
<robot name="abb_crb15000_5_95">
  <link name="base_link">
    <visual>
      <origin rpy="0.0 0.0 0.0" xyz="0.0 0.0 0.0"/>
      <geometry>
        <mesh filename="meshes/crb15000_5_95/visual/base_link.dae"/>
      </geometry>
      <material name="light_grey">
        <color rgba="0.6 0.6 0.6 1.0"/>
      </material>
    </visual>
    <collision>
      <origin rpy="0.0 0.0 0.0" xyz="0.0 0.0 0.0"/>
      <geometry>
        <mesh filename="meshes/crb15000_5_95/collision/base_link.dae"/>
      </geometry>
    </collision>
    <inertial>
      <origin rpy="0.0 0.0 0.0" xyz="0.0 0.0 0.0"/>
      <mass value="3.5"/>
      <inertia ixx="0.015" ixy="0.0" ixz="0.0" iyy="0.016" iyz="0.0" izz="0.01"/>
    </inertial>
  </link>
  <link name="link_1">
    <visual>
      <origin rpy="0.0 0.0 0.0" xyz="0.0 0.0 0.0"/>
      <geometry>
        <mesh filename="meshes/crb15000_5_95/visual/link_1.dae"/>
      </geometry>
      <material name="light_grey">
        <color rgba="0.6 0.6 0.6 1.0"/>
      </material>
    </visual>
    <collision>
      <origin rpy="0.0 0.0 0.0" xyz="0.0 0.0 0.0"/>
      <geometry>
        <mesh filename="meshes/crb15000_5_95/collision/link_1.dae"/>
      </geometry>
    </collision>
    <inertial>
      <origin rpy="0.0 0.0 0.0" xyz="0.0 0.0 0.0"/>
      <mass value="2.8"/>
      <inertia ixx="0.01" ixy="0.0" ixz="0.0" iyy="0.006" iyz="0.0" izz="0.01"/>
    </inertial>
  </link>
  <link name="link_2">
    <visual>
      <origin rpy="0.0 0.0 0.0" xyz="0.0 0.0 0.0"/>
      <geometry>
        <mesh filename="meshes/crb15000_5_95/visual/link_2.dae"/>
      </geometry>
      <material name="light_grey">
        <color rgba="0.6 0.6 0.6 1.0"/>
      </material>
    </visual>
    <collision>
      <origin rpy="0.0 0.0 0.0" xyz="0.0 0.0 0.0"/>
      <geometry>
        <mesh filename="meshes/crb15000_5_95/collision/link_2.dae"/>
      </geometry>
    </collision>
    <inertial>
      <origin rpy="0.0 0.0 0.0" xyz="0.0 0.0 0.0"/>
      <mass value="4.29"/>
      <inertia ixx="0.13" ixy="0.0" ixz="0.0" iyy="0.13" iyz="0.0" izz="0.006"/>
    </inertial>
  </link>
  <link name="link_3">
    <visual>
      <origin rpy="0.0 0.0 0.0" xyz="0.0 0.0 0.0"/>
      <geometry>
        <mesh filename="meshes/crb15000_5_95/visual/link_3.dae"/>
      </geometry>
      <material name="light_grey">
        <color rgba="0.6 0.6 0.6 1.0"/>
      </material>
    </visual>
    <collision>
      <origin rpy="0.0 0.0 0.0" xyz="0.0 0.0 0.0"/>
      <geometry>
        <mesh filename="meshes/crb15000_5_95/collision/link_3.dae"/>
      </geometry>
    </collision>
    <inertial>
      <origin rpy="0.0 0.0 0.0" xyz="0.0 0.0 0.0"/>
      <mass value="3.4"/>
      <inertia ixx="0.017" ixy="0.0" ixz="0.0" iyy="0.014" iyz="0.0" izz="0.013"/>
    </inertial>
  </link>
  <link name="link_4">
    <visual>
      <origin rpy="0.0 0.0 0.0" xyz="0.0 0.0 0.0"/>
      <geometry>
        <mesh filename="meshes/crb15000_5_95/visual/link_4.dae"/>
      </geometry>
      <material name="light_grey">
        <color rgba="0.6 0.6 0.6 1.0"/>
      </material>
    </visual>
    <collision>
      <origin rpy="0.0 0.0 0.0" xyz="0.0 0.0 0.0"/>
      <geometry>
        <mesh filename="meshes/crb15000_5_95/collision/link_4.dae"/>
      </geometry>
    </collision>
    <inertial>
      <origin rpy="0.0 0.0 0.0" xyz="0.0 0.0 0.0"/>
      <mass value="2.8"/>
      <inertia ixx="0.009" ixy="-0.01" ixz="0.0" iyy="0.034" iyz="0.0" izz="0.038"/>
    </inertial>
  </link>
  <link name="link_5">
    <visual>
      <origin rpy="0.0 0.0 0.0" xyz="0.0 0.0 0.0"/>
      <geometry>
        <mesh filename="meshes/crb15000_5_95/visual/link_5.dae"/>
      </geometry>
      <material name="light_grey">
        <color rgba="0.6 0.6 0.6 1.0"/>
      </material>
    </visual>
    <collision>
      <origin rpy="0.0 0.0 0.0" xyz="0.0 0.0 0.0"/>
      <geometry>
        <mesh filename="meshes/crb15000_5_95/collision/link_5.dae"/>
      </geometry>
    </collision>
    <inertial>
      <origin rpy="0.0 0.0 0.0" xyz="0.0 0.0 0.0"/>
      <mass value="3.0"/>
      <inertia ixx="0.011" ixy="0.0" ixz="0.0" iyy="0.013" iyz="0.0" izz="0.01"/>
    </inertial>
  </link>
  <link name="link_6">
    <visual>
      <origin rpy="0.0 0.0 0.0" xyz="0.0 0.0 0.0"/>
      <geometry>
        <mesh filename="meshes/crb15000_5_95/visual/link_6.dae"/>
      </geometry>
      <material name="light_grey">
        <color rgba="0.6 0.6 0.6 1.0"/>
      </material>
    </visual>
    <collision>
      <origin rpy="0.0 0.0 0.0" xyz="0.0 0.0 0.0"/>
      <geometry>
        <mesh filename="meshes/crb15000_5_95/collision/link_6.dae"/>
      </geometry>
    </collision>
    <inertial>
      <origin rpy="0.0 0.0 0.0" xyz="0.0 0.0 0.0"/>
      <mass value="0.15"/>
      <inertia ixx="0.0001" ixy="0.0" ixz="0.0" iyy="1e-06" iyz="0.0" izz="1e-06"/>
    </inertial>
  </link>
  <link name="flange">
    <inertial>
      <mass value="0.01"/>
      <inertia ixx="1.66666667e-05" ixy="0.0" ixz="0.0" iyy="1.66666667e-05" iyz="0.0" izz="1.66666667e-05"/>
    </inertial>
  </link>
  <link name="tool0">
    <inertial>
      <mass value="0.01"/>
      <inertia ixx="1.66666667e-05" ixy="0.0" ixz="0.0" iyy="1.66666667e-05" iyz="0.0" izz="1.66666667e-05"/>
    </inertial>
  </link>
  <joint name="joint_1" type="revolute">
    <parent link="base_link"/>
    <child link="link_1"/>
    <origin rpy="0.0 0.0 0.0" xyz="0.0 0.0 0.0"/>
    <axis xyz="0.0 0.0 1.0"/>
    <limit effort="0.0" lower="-3.141592653589793" upper="3.141592653589793" velocity="0.0"/>
    <dynamics damping="0.0" friction="0.0"/>
  </joint>
  <joint name="joint_2" type="revolute">
    <parent link="link_1"/>
    <child link="link_2"/>
    <origin rpy="0.0 0.0 0.0" xyz="0.0 -0.086 0.265"/>
    <axis xyz="0.0 1.0 0.0"/>
    <limit effort="0.0" lower="-3.141592653589793" upper="3.141592653589793" velocity="0.0"/>
    <dynamics damping="0.0" friction="0.0"/>
  </joint>
  <joint name="joint_3" type="revolute">
    <parent link="link_2"/>
    <child link="link_3"/>
    <origin rpy="0.0 0.0 0.0" xyz="0.0 0.001 0.444"/>
    <axis xyz="0.0 1.0 0.0"/>
    <limit effort="0.0" lower="-3.9269908169872414" upper="1.4835298641951802" velocity="0.0"/>
    <dynamics damping="0.0" friction="0.0"/>
  </joint>
  <joint name="joint_4" type="revolute">
    <parent link="link_3"/>
    <child link="link_4"/>
    <origin rpy="0.0 0.0 0.0" xyz="0.097 0.085 0.11"/>
    <axis xyz="1.0 0.0 0.0"/>
    <limit effort="0.0" lower="-3.141592653589793" upper="3.141592653589793" velocity="0.0"/>
    <dynamics damping="0.0" friction="0.0"/>
  </joint>
  <joint name="joint_5" type="revolute">
    <parent link="link_4"/>
    <child link="link_5"/>
    <origin rpy="0.0 0.0 0.0" xyz="0.373 0.0745 0.0"/>
    <axis xyz="0.0 1.0 0.0"/>
    <limit effort="0.0" lower="-3.141592653589793" upper="3.141592653589793" velocity="0.0"/>
    <dynamics damping="0.0" friction="0.0"/>
  </joint>
  <joint name="joint_6" type="revolute">
    <parent link="link_5"/>
    <child link="link_6"/>
    <origin rpy="0.0 0.0 0.0" xyz="0.0684 -0.0745 0.08"/>
    <axis xyz="1.0 0.0 0.0"/>
    <limit effort="0.0" lower="-4.71238898038469" upper="4.71238898038469" velocity="0.0"/>
    <dynamics damping="0.0" friction="0.0"/>
  </joint>
  <joint name="joint_6_flange" type="fixed">
    <parent link="link_6"/>
    <child link="flange"/>
    <origin rpy="0.0 0.0 0.0" xyz="0.0326 0.0 -0.0001"/>
  </joint>
  <joint name="flange_tool0" type="fixed">
    <parent link="flange"/>
    <child link="tool0"/>
    <origin rpy="0.0 1.5707963267948966 0.0" xyz="0.0 0.0 0.0"/>
  </joint>
  <transmission name="transmission_1">
    <type>transmission_interface/SimpleTransmission</type>
    <joint name="joint_1">
      <hardwareInterface>hardware_interface/PositionJointInterface</hardwareInterface>
    </joint>
    <actuator name="joint_1_motor">
      <mechanicalReduction>1.0</mechanicalReduction>
    </actuator>
  </transmission>
  <transmission name="transmission_2">
    <type>transmission_interface/SimpleTransmission</type>
    <joint name="joint_2">
      <hardwareInterface>hardware_interface/PositionJointInterface</hardwareInterface>
    </joint>
    <actuator name="joint_2_motor">
      <mechanicalReduction>1.0</mechanicalReduction>
    </actuator>
  </transmission>
  <transmission name="transmission_3">
    <type>transmission_interface/SimpleTransmission</type>
    <joint name="joint_3">
      <hardwareInterface>hardware_interface/PositionJointInterface</hardwareInterface>
    </joint>
    <actuator name="joint_3_motor">
      <mechanicalReduction>1.0</mechanicalReduction>
    </actuator>
  </transmission>
  <transmission name="transmission_4">
    <type>transmission_interface/SimpleTransmission</type>
    <joint name="joint_4">
      <hardwareInterface>hardware_interface/PositionJointInterface</hardwareInterface>
    </joint>
    <actuator name="joint_4_motor">
      <mechanicalReduction>1.0</mechanicalReduction>
    </actuator>
  </transmission>
  <transmission name="transmission_5">
    <type>transmission_interface/SimpleTransmission</type>
    <joint name="joint_5">
      <hardwareInterface>hardware_interface/PositionJointInterface</hardwareInterface>
    </joint>
    <actuator name="joint_5_motor">
      <mechanicalReduction>1.0</mechanicalReduction>
    </actuator>
  </transmission>
  <transmission name="transmission_6">
    <type>transmission_interface/SimpleTransmission</type>
    <joint name="joint_6">
      <hardwareInterface>hardware_interface/PositionJointInterface</hardwareInterface>
    </joint>
    <actuator name="joint_6_motor">
      <mechanicalReduction>1.0</mechanicalReduction>
    </actuator>
  </transmission>
  <gazebo reference="base_link">
    <turnGravityOff>True</turnGravityOff>
  </gazebo>
  <gazebo reference="link_1">
    <turnGravityOff>True</turnGravityOff>
  </gazebo>
  <gazebo reference="link_2">
    <turnGravityOff>True</turnGravityOff>
  </gazebo>
  <gazebo reference="link_3">
    <turnGravityOff>True</turnGravityOff>
  </gazebo>
  <gazebo reference="link_4">
    <turnGravityOff>True</turnGravityOff>
  </gazebo>
  <gazebo reference="link_5">
    <turnGravityOff>True</turnGravityOff>
  </gazebo>
  <gazebo reference="link_6">
    <turnGravityOff>True</turnGravityOff>
  </gazebo>
</robot>
